<?xml version="1.0" ?>
<!-- =================================================================================== -->
<!-- |    This document was autogenerated by xacro from irb6660_205_190.xacro          | -->
<!-- |    EDITING THIS FILE BY HAND IS NOT RECOMMENDED                                 | -->
<!-- =================================================================================== -->
<robot name="abb_irb6660_205_190" xmlns:xacro="http://ros.org/wiki/xacro">
  <!-- Conversion were obtained from http://www.e-paint.co.uk/Lab_values.asp
       unless otherwise stated. -->
  <!-- link list -->
  <link name="base_link">
    <visual>
      <origin rpy="0 0 0" xyz="0 0 0"/>
      <geometry>
        <mesh filename="package://abb_irb6660_support/meshes/irb6660/visual/base_link.stl"/>
      </geometry>
      <material name="">
        <color rgba="0.7372549 0.3490196 0.1607843 1"/>
      </material>
    </visual>
    <collision>
      <geometry>
        <mesh filename="package://abb_irb6660_support/meshes/irb6660/collision/base_link.stl"/>
      </geometry>
      <material name="">
        <color rgba="1 1 0 1"/>
      </material>
    </collision>
  </link>
  <link name="link_1">
    <visual>
      <origin rpy="0 0 0" xyz="0 0 0"/>
      <geometry>
        <mesh filename="package://abb_irb6660_support/meshes/irb6660/visual/link_1.stl"/>
      </geometry>
      <material name="">
        <color rgba="0.7372549 0.3490196 0.1607843 1"/>
      </material>
    </visual>
    <collision>
      <origin rpy="0 0 0" xyz="0 0 0"/>
      <geometry>
        <mesh filename="package://abb_irb6660_support/meshes/irb6660/collision/link_1.stl"/>
      </geometry>
      <material name="">
        <color rgba="1 1 0 1"/>
      </material>
    </collision>
  </link>
  <link name="link_2">
    <visual>
      <origin rpy="0 0 0" xyz="0 0 0"/>
      <geometry>
        <mesh filename="package://abb_irb6660_support/meshes/irb6660_205_190/visual/link_2.stl"/>
      </geometry>
      <material name="">
        <color rgba="0.7372549 0.3490196 0.1607843 1"/>
      </material>
    </visual>
    <collision>
      <origin rpy="0 0 0" xyz="0 0 0"/>
      <geometry>
        <mesh filename="package://abb_irb6660_support/meshes/irb6660_205_190/collision/link_2.stl"/>
      </geometry>
      <material name="">
        <color rgba="1 1 0 1"/>
      </material>
    </collision>
  </link>
  <link name="link_3">
    <visual>
      <origin rpy="0 0 0" xyz="0 0 0"/>
      <geometry>
        <mesh filename="package://abb_irb6660_support/meshes/irb6660/visual/link_3.stl"/>
      </geometry>
      <material name="">
        <color rgba="0.7372549 0.3490196 0.1607843 1"/>
      </material>
    </visual>
    <collision>
      <origin rpy="0 0 0" xyz="0 0 0"/>
      <geometry>
        <mesh filename="package://abb_irb6660_support/meshes/irb6660/collision/link_3.stl"/>
      </geometry>
      <material name="">
        <color rgba="1 1 0 1"/>
      </material>
    </collision>
  </link>
  <link name="link_4">
    <visual>
      <origin rpy="0 0 0" xyz="0 0 0"/>
      <geometry>
        <mesh filename="package://abb_irb6660_support/meshes/irb6660_205_190/visual/link_4.stl"/>
      </geometry>
      <material name="">
        <color rgba="0.7372549 0.3490196 0.1607843 1"/>
      </material>
    </visual>
    <collision>
      <origin rpy="0 0 0" xyz="0 0 0"/>
      <geometry>
        <mesh filename="package://abb_irb6660_support/meshes/irb6660_205_190/collision/link_4.stl"/>
      </geometry>
      <material name="">
        <color rgba="1 1 0 1"/>
      </material>
    </collision>
  </link>
  <link name="link_5">
    <visual>
      <origin rpy="0 0 0" xyz="0 0 0"/>
      <geometry>
        <mesh filename="package://abb_irb6660_support/meshes/irb6660/visual/link_5.stl"/>
      </geometry>
      <material name="">
        <color rgba="0.7372549 0.3490196 0.1607843 1"/>
      </material>
    </visual>
    <collision>
      <origin rpy="0 0 0" xyz="0 0 0"/>
      <geometry>
        <mesh filename="package://abb_irb6660_support/meshes/irb6660/collision/link_5.stl"/>
      </geometry>
      <material name="">
        <color rgba="1 1 0 1"/>
      </material>
    </collision>
  </link>
  <link name="link_6">
    <visual>
      <origin rpy="0 0 0" xyz="0 0 0"/>
      <geometry>
        <mesh filename="package://abb_irb6660_support/meshes/irb6660/visual/link_6.stl"/>
      </geometry>
      <material name="">
        <color rgba="0.1882353 0.1960784 0.2039216 1"/>
      </material>
    </visual>
    <collision>
      <origin rpy="0 0 0" xyz="0 0 0"/>
      <geometry>
        <mesh filename="package://abb_irb6660_support/meshes/irb6660/collision/link_6.stl"/>
      </geometry>
      <material name="">
        <color rgba="1 1 0 1"/>
      </material>
    </collision>
  </link>
  <!-- Balancer parallell to Link 2 -->
  <link name="balancer">
    <visual>
      <!-- <origin xyz="0.2 0.0 -0.8145" rpy="0 0 0" /> -->
      <origin rpy="0 0 0" xyz="0 0 0"/>
      <geometry>
        <mesh filename="package://abb_irb6660_support/meshes/irb6660_205_190/visual/link_bar.stl"/>
      </geometry>
      <material name="">
        <color rgba="0.7372549 0.3490196 0.1607843 1"/>
      </material>
    </visual>
    <collision>
      <!-- <origin xyz="0.2 0.0 -0.8145" rpy="0 0 0" /> -->
      <origin rpy="0 0 0" xyz="0 0 0"/>
      <geometry>
        <mesh filename="package://abb_irb6660_support/meshes/irb6660_205_190/collision/link_bar.stl"/>
      </geometry>
    </collision>
    <material name="">
      <color rgba="0.7372549 0.3490196 0.1607843 1"/>
    </material>
  </link>
  <!-- Link Arm parallell to Link 3 -->
  <link name="link_arm">
    <visual>
      <origin rpy="0 0 0" xyz="0 0 0"/>
      <geometry>
        <mesh filename="package://abb_irb6660_support/meshes/irb6660/visual/link_arm.stl"/>
      </geometry>
      <material name="">
        <color rgba="0.7372549 0.3490196 0.1607843 1"/>
      </material>
    </visual>
    <collision>
      <origin rpy="0 0 0" xyz="0 0 0"/>
      <geometry>
        <mesh filename="package://abb_irb6660_support/meshes/irb6660/collision/link_arm.stl"/>
      </geometry>
    </collision>
    <material name="">
      <color rgba="0.7372549 0.3490196 0.1607843 1"/>
    </material>
  </link>
  <!-- <link name="${prefix}link_arm"/> -->
  <link name="fakelink_1"/>
  <link name="tool0"/>
  <!-- End of Link List -->
  <!-- Joint List -->
  <!-- Joint 1 -Axis -->
  <joint name="joint_1" type="revolute">
    <origin rpy="0 0 0" xyz="0 0 0.8145"/>
    <parent link="base_link"/>
    <child link="link_1"/>
    <axis xyz="0 0 1"/>
    <limit effort="0" lower="-3.14159265359" upper="3.14159265359" velocity="2.26892802759"/>
  </joint>
  <!-- Joint 2 -Axis -->
  <joint name="joint_2" type="revolute">
    <origin rpy="0 0 0" xyz="0.300 0 0"/>
    <parent link="link_1"/>
    <child link="link_2"/>
    <axis xyz="0 1 0"/>
    <limit effort="0" lower="-0.733038285838" upper="1.4835298642" velocity="2.26892802759"/>
  </joint>
  <!-- Joint 3 -Axis -->
  <joint name="joint_3" type="revolute">
    <origin rpy="0 0 0" xyz="0 0 0.700"/>
    <parent link="link_2"/>
    <child link="link_3"/>
    <axis xyz="0 1 0"/>
    <limit effort="0" lower="-1.2217304764" upper="1.2217304764" velocity="2.26892802759"/>
  </joint>
  <!-- Joint 4 -Axis -->
  <joint name="joint_4" type="revolute">
    <origin rpy="0 0 0" xyz="0 0 0.280"/>
    <parent link="link_3"/>
    <child link="link_4"/>
    <axis xyz="1 0 0"/>
    <limit effort="0" lower="-5.23598775598" upper="5.23598775598" velocity="2.61799387799"/>
  </joint>
  <!-- Joint 5 -Axis -->
  <joint name="joint_5" type="revolute">
    <origin rpy="0 0 0" xyz="0.893 0 0"/>
    <parent link="link_4"/>
    <child link="link_5"/>
    <axis xyz="0 1 0"/>
    <limit effort="0" lower="-2.09439510239" upper="2.09439510239" velocity="2.09439510239"/>
  </joint>
  <!-- Joint 6 -Axis -->
  <joint name="joint_6" type="revolute">
    <origin rpy="0 0 0" xyz="0.200 0 0"/>
    <parent link="link_5"/>
    <child link="link_6"/>
    <axis xyz="1 0 0"/>
    <limit effort="0" lower="-6.28318530718" upper="6.28318530718" velocity="3.31612557879"/>
  </joint>
  <!-- EOAT -->
  <joint name="joint_6-tool0" type="fixed">
    <origin rpy="0 1.57079632679 0" xyz="0 0 0"/>
    <parent link="link_6"/>
    <child link="tool0"/>
  </joint>
  <joint name="link1_adjustment" type="revolute">
    <origin rpy="0 0 0" xyz="0.300 0 0"/>
    <parent link="link_1"/>
    <child link="fakelink_1"/>
    <axis xyz="0 1 0"/>
    <mimic joint="joint_2" multiplier="1"/>
    <limit effort="0" lower="-1.2217304764" upper="1.2217304764" velocity="2.26892802759"/>
  </joint>
  <joint name="link_arm" type="revolute">
    <origin rpy="0 0 0" xyz="0 0 0"/>
    <parent link="fakelink_1"/>
    <child link="link_arm"/>
    <axis xyz="0 1 0"/>
    <mimic joint="joint_3" multiplier="1"/>
    <limit effort="0" lower="-1.2217304764" upper="1.2217304764" velocity="2.26892802759"/>
  </joint>
  <joint name="balancer" type="revolute">
    <!--Named balancer only to be interchangeable with motoman without errors-->
    <parent link="link_arm"/>
    <child link="balancer"/>
    <origin rpy="0 0 0" xyz="-0.5 0 0"/>
    <axis xyz="0 1 0"/>
    <mimic joint="joint_3" multiplier="-1"/>
    <limit effort="0" lower="-1.2217304764" upper="1.2217304764" velocity="2.26892802759"/>
  </joint>
  <!-- End of joint List -->
  <!-- ROS base_link to ABB World Coordinates transform -->
  <link name="base"/>
  <joint name="base_link-base" type="fixed">
    <origin rpy="0 0 0" xyz="0 0 0"/>
    <parent link="base_link"/>
    <child link="base"/>
  </joint>
</robot>
