<?xml version="1.0"?>
<robot xmlns:xacro="http://ros.org/wiki/xacro">
  <xacro:include filename="$(find abb_resources)/urdf/common_materials.xacro"/>
  <xacro:macro name="abb_irb6660_205_190" params="prefix">

    <!-- link list -->
    <link name="${prefix}base_link">
      <visual>
        <origin xyz="0 0 0" rpy="0 0 0"/>
        <geometry>
          <mesh filename="package://abb_irb6660_support/meshes/irb6660/visual/base_link.stl"/>
        </geometry>
        <xacro:material_abb_orange />
      </visual>
      <collision>
        <geometry>
          <mesh filename="package://abb_irb6660_support/meshes/irb6660/collision/base_link.stl"/>
        </geometry>
        <xacro:material_abb_yellow />
      </collision>
    </link>

    <link name="${prefix}link_1">
      <visual>
        <origin xyz="0 0 0" rpy="0 0 0"/>
        <geometry>
          <mesh filename="package://abb_irb6660_support/meshes/irb6660/visual/link_1.stl"/>
        </geometry>
        <xacro:material_abb_orange />
      </visual>
      <collision>
        <origin xyz="0 0 0" rpy="0 0 0"/>
        <geometry>
          <mesh filename="package://abb_irb6660_support/meshes/irb6660/visual/link_1.stl"/>
        </geometry>
        <xacro:material_abb_yellow />
      </collision>
    </link>

    <link name="${prefix}link_2">
      <visual>
        <origin xyz="0 0 0" rpy="0 0 0"/>
        <geometry>
          <mesh filename="package://abb_irb6660_support/meshes/irb6660_205_190/visual/link_2.stl"/>
        </geometry>
        <xacro:material_abb_orange />
      </visual>
      <collision>
        <origin xyz="0 0 0" rpy="0 0 0"/>
        <geometry>
          <mesh filename="package://abb_irb6660_support/meshes/irb6660_205_190/collision/link_2.stl"/>
        </geometry>
        <xacro:material_abb_yellow />
      </collision>
    </link>

    <link name="${prefix}link_3">
      <visual>
        <origin xyz="0 0 0" rpy="0 0 0"/>
        <geometry>
          <mesh filename="package://abb_irb6660_support/meshes/irb6660/visual/link_3.stl"/>
        </geometry>
        <xacro:material_abb_orange />
      </visual>
      <collision>
        <origin xyz="0 0 0" rpy="0 0 0"/>
        <geometry>
          <mesh filename="package://abb_irb6660_support/meshes/irb6660/collision/link_3.stl"/>
        </geometry>
        <xacro:material_abb_yellow />
      </collision>
    </link>

    <link name="${prefix}link_4">
      <visual>
        <origin xyz="0 0 0" rpy="0 0 0"/>
        <geometry>
          <mesh filename="package://abb_irb6660_support/meshes/irb6660_205_190/visual/link_4.stl"/>
        </geometry>
        <xacro:material_abb_orange />
      </visual>
      <collision>
        <origin xyz="0 0 0" rpy="0 0 0"/>
        <geometry>
            <mesh filename="package://abb_irb6660_support/meshes/irb6660_205_190/collision/link_4.stl"/>
        </geometry>
        <xacro:material_abb_yellow />
      </collision>
    </link>

    <link name="${prefix}link_5">
      <visual>
        <origin xyz="0 0 0" rpy="0 0 0"/>
        <geometry>
          <mesh filename="package://abb_irb6660_support/meshes/irb6660/visual/link_5.stl"/>
        </geometry>
        <xacro:material_abb_orange />
      </visual>
      <collision>
        <origin xyz="0 0 0" rpy="0 0 0"/>
        <geometry>
          <mesh filename="package://abb_irb6660_support/meshes/irb6660/collision/link_5.stl"/>
        </geometry>
        <xacro:material_abb_yellow />
      </collision>
    </link>

    <link name="${prefix}link_6">
      <visual>
        <origin xyz="0 0 0" rpy="0 0 0"/>
        <geometry>
          <mesh filename="package://abb_irb6660_support/meshes/irb6660/visual/link_6.stl"/>
        </geometry>
        <xacro:material_abb_black />
      </visual>
      <collision>
        <origin xyz="0 0 0" rpy="0 0 0"/>
        <geometry>
          <mesh filename="package://abb_irb6660_support/meshes/irb6660/collision/link_6.stl"/>
        </geometry>
        <xacro:material_abb_yellow />
      </collision>
    </link>

    <!-- Balancer parallell to Link 2 -->
    <link name="${prefix}balancer">
        <visual>
            <!-- <origin xyz="0.2 0.0 -0.8145" rpy="0 0 0" /> -->
            <origin xyz="0 0 0" rpy="0 0 0"/>
            <geometry>
                <mesh filename="package://abb_irb6660_support/meshes/irb6660_205_190/visual/link_bar.stl"/>
            </geometry>
            <xacro:material_abb_orange />
        </visual>
        <collision>
            <!-- <origin xyz="0.2 0.0 -0.8145" rpy="0 0 0" /> -->
            <origin xyz="0 0 0" rpy="0 0 0"/>
            <geometry>
                <mesh filename="package://abb_irb6660_support/meshes/irb6660_205_190/collision/link_bar.stl"/>
            </geometry>
        </collision>
        <xacro:material_abb_orange />
    </link>

    <!-- Link Arm parallell to Link 3 -->
    <link name="${prefix}link_arm">
        <visual>
            <origin xyz="0 0 0" rpy="0 0 0"/>
            <geometry>
                <mesh filename="package://abb_irb6660_support/meshes/irb6660/visual/link_arm.stl"/>
            </geometry>
            <xacro:material_abb_orange />
        </visual>
        <collision>
            <origin xyz="0 0 0" rpy="0 0 0"/>
            <geometry>
                <mesh filename="package://abb_irb6660_support/meshes/irb6660/collision/link_arm.stl"/>
            </geometry>
        </collision>
        <xacro:material_abb_orange />
    </link>

    <!-- <link name="${prefix}link_arm"/> -->
    <link name="${prefix}fakelink"/>
    <link name="${prefix}tool0"/>
    <!-- End of Link List -->

    <!-- Joint List -->
    <!-- Joint 1 -Axis -->
    <joint name="${prefix}joint_1" type="revolute">
      <origin xyz="0 0 0.8145" rpy="0 0 0"/>
      <parent link="${prefix}base_link"/>
      <child link="${prefix}link_1"/>
      <axis xyz="0 0 1"/>
      <limit lower="-${radians(180)}" upper="${radians(180)}" effort="0" velocity="${radians(130)}"/>
    </joint>

    <!-- Joint 2 -Axis -->
    <joint name="${prefix}joint_2" type="revolute">
      <origin xyz="0.300 0 0" rpy="0 0 0"/>
      <parent link="${prefix}link_1"/>
      <child link="${prefix}link_2"/>
      <axis xyz="0 1 0"/>
      <limit lower="-${radians(42)}" upper="${radians(85)}" effort="0" velocity="${radians(130)}"/>
    </joint>

    <!-- Joint 3 -Axis -->
    <joint name="${prefix}joint_3" type="revolute">
      <origin xyz="0 0 0.700" rpy="0 0 0"/>
      <parent link="${prefix}link_2"/>
      <child link="${prefix}link_3"/>
      <axis xyz="0 1 0"/>
      <limit lower="-${radians(70)}" upper="${radians(70)}" effort="0" velocity="${radians(130)}"/>
    </joint>

    <!-- Joint 4 -Axis -->
    <joint name="${prefix}joint_4" type="revolute">
      <origin xyz="0 0 0.280" rpy="0 0 0"/>
      <parent link="${prefix}link_3"/>
      <child link="${prefix}link_4"/>
      <axis xyz="1 0 0"/>
      <limit lower="-${radians(300)}" upper="${radians(300)}" effort="0" velocity="${radians(150)}"/>
    </joint>

    <!-- Joint 5 -Axis -->
    <joint name="${prefix}joint_5" type="revolute">
      <origin xyz="0.893 0 0" rpy="0 0 0"/>
      <parent link="${prefix}link_4"/>
      <child link="${prefix}link_5"/>
      <axis xyz="0 1 0"/>
      <limit lower="-${radians(120)}" upper="${radians(120)}" effort="0" velocity="${radians(120)}"/>
    </joint>

    <!-- Joint 6 -Axis -->
    <joint name="${prefix}joint_6" type="revolute">
      <origin xyz="0.200 0 0" rpy="0 0 0"/>
      <parent link="${prefix}link_5"/>
      <child link="${prefix}link_6"/>
      <axis xyz="1 0 0"/>
      <limit lower="-${radians(360)}" upper="${radians(360)}" effort="0" velocity="${radians(190)}"/>
    </joint>

    <!-- EOAT -->
    <joint name="${prefix}joint_6-tool0" type="fixed">
      <origin xyz="0 0 0" rpy="0 ${radians(90)} 0"/>
      <parent link="${prefix}link_6"/>
      <child link="${prefix}tool0"/>
    </joint>

    

    <joint name="${prefix}link1_adjustment" type="revolute">
      <origin xyz="0.300 0 0" rpy="0 0 0"/>
      <parent link="${prefix}link_1"/>
      <child link="${prefix}fakelink"/>
      <axis xyz="0 1 0"/>
      <mimic joint="${prefix}joint_2" multiplier="1"/>
      <limit lower="-${radians(70)}" upper="${radians(70)}" effort="0" velocity="${radians(130)}"/>
    </joint>

    <joint name="${prefix}link_arm" type="revolute">
      <origin xyz="0 0 0" rpy="0 0 0"/>
      <parent link="${prefix}fakelink"/>
      <child link="${prefix}link_arm"/>
      <axis xyz="0 1 0"/>
      <mimic joint="${prefix}joint_3" multiplier="1"/>
      <limit lower="-${radians(70)}" upper="${radians(70)}" effort="0" velocity="${radians(130)}"/>
    </joint>

    <joint name="${prefix}balancer" type="revolute"> <!--Named balancer only to be interchangeable with motoman without errors-->
        <parent link="${prefix}link_arm"/>
        <child link="${prefix}balancer"/>
        <origin xyz="-0.5 0 0" rpy="0 0 0"/>
        <axis xyz="0 1 0" />
        <mimic joint="${prefix}joint_3" multiplier="-1"/>
        <limit lower="-${radians(70)}" upper="${radians(70)}" effort="0" velocity="${radians(130)}"/>
    </joint>

    <!-- End of joint List -->

    <!-- ROS base_link to ABB World Coordinates transform -->
    <link name="${prefix}base" />
    <joint name="${prefix}base_link-base" type="fixed">
      <origin xyz="0 0 0" rpy="0 0 0"/>
      <parent link="${prefix}base_link"/>
      <child link="${prefix}base"/>
    </joint>

  </xacro:macro>
</robot>
